<?xml version="1.0" ?>
<!--This file contains the SDF model of a KUKA iiwa robot with a wsg50 gripper.
    It has been produced from the varients in //third_party/robotics/models.
    Note:  This file is temporary, and should be deleted once Bullet supports
    importing models in SDF.  Also, this file has been specialized for Bullet,
    because the mass of the base link has been set to 0, as needed by Bullet.
    Note:  All of the gripper link poses have been adjusted in the z direction
    to achieve a reasonable position of the gripper relative to the arm.
    Note: The joint names for the KUKA have been changed to J0, J1, etc. -->
    <!--There is problem with the kuka mesh and everytime i use it gazebo crashes so I am gonna comment that part-->


<sdf version='1.6'>
  <model name="kuka_handlit">
    # <static>true</static>    
    <link name = "world">
        <pose frame=''>0 0 0 0 0 0</pose>
        <inertial>
            <pose frame=''>0 0 0.0 0 0 0</pose>
            <mass>0.0</mass>
            <inertia>
                <ixx>0.</ixx>
                <ixy>0</ixy>
                <ixz>0</ixz>
                <iyy>0.</iyy>
                <iyz>0</iyz>
                <izz>0.</izz>
            </inertia>
        </inertial>
    </link>

    <joint name="forearm_world" type="fixed">
        <child>forearm</child>
        <parent>world</parent>
    </joint>

    <!--Hand-->


    <link name ="forearm" >
        <pose frame=''>0 0 0 0 0 1.5707963267948966</pose>
        <inertial>
            <pose frame=''>0 0 0.09 0 0 0</pose>
            <mass>1.8</mass>
            <inertia>
                <ixx>0.108</ixx>
                <ixy>0</ixy>
                <ixz>0</ixz>
                <iyy>0.108</iyy>
                <iyz>0</iyz>
                <izz>0.054</izz>
            </inertia>
        </inertial>

        <visual name='visual_forearm_link'>

            <geometry>
                <mesh>
                    <scale>1 1 1</scale>
                    <uri>/meshes/forearm_lite.dae</uri>
                </mesh>
            </geometry>
            <material>
                <ambient>0.2361051783749406 0.08209714284500236 0.10391787777390704 1</ambient>
                <diffuse>0.9923048747596346 0.4067909462509247 0.36604267727209117 1</diffuse>
                <specular>0.31942109221779136 0.2606995704718581 0.1450750986125534 1</specular>
                <emissive>0 0 0 0</emissive>
            </material>
        </visual>
        <collision name='collision_forearm_link'>
        
            <geometry>
                <mesh>
                    <scale>1 1 1</scale>
                    <uri>/meshes/forearm_lite.dae</uri>
                </mesh>
            </geometry>
        </collision>
    </link>

    <link name = "palm">
        <pose frame=''>0 -0.015 0.149 -0.6981317007977318 0 0</pose>
        <inertial>
            <pose frame=''>0 0 0.035 0 0 0</pose>
            <mass>0.3</mass>
            <inertia>
                <ixx>0.0003581</ixx>
                <ixy>0</ixy>
                <ixz>0</ixz>
                <iyy>0.0005287</iyy>
                <iyz>0</iyz>
                <izz>0.000191</izz>
            </inertia>
        </inertial>
        
        <visual name='visual_palm_link'>

            <geometry>
                <mesh>
                    <scale>-0.001 0.001 0.001</scale>
                    <uri>/meshes/palm2.dae</uri>
                </mesh>
            </geometry>
            <material>
                <ambient>0.39444860723254627 0.5167308893667778 0.4128076928633102 1</ambient>
                <diffuse>0.9853989547855541 0.5316949964824096 0.1109699757147613 1</diffuse>
                <specular>0.5462849559171041 0.9997088824501734 0.04540650600785412 1</specular>
                <emissive>0 0 0 0</emissive>
            </material>
        </visual>
        <collision name="collision_palm_link">

            <geometry>
                <mesh>
                    <scale>-0.001 0.001 0.001</scale>
                <uri>/meshes/palm2_c.dae</uri>
            </mesh>
            </geometry>
        </collision>


        
    </link>
    <joint name="palm_forearm" type="fixed">
        <child>palm</child>
        <parent>forearm</parent>
        <axis>

            <xyz>0 -1 0</xyz>
         </axis>
    </joint>  

    
    <link name = "palm_fake">

        <pose frame=''>-0.01 0.020909000000000004 0.1889 -0.6981317007977318 0 0</pose>
        <inertial>
            <pose frame=''>0 0 0.0 0 0 0</pose>
            <mass>1.0e-85</mass>
            <inertia>
                <ixx>0.0</ixx>
                <ixy>0</ixy>
                <ixz>0</ixz>
                <iyy>0.0</iyy>
                <iyz>0</iyz>
                <izz>0.0</izz>
            </inertia>
        </inertial>
        <visual name='visual_palm_fake'>
            <geometry>
                <sphere>
                <radius>0.01</radius>
                </sphere>
            </geometry>
            <material>
                <ambient>0.5672216218105076 0.531815859282997 0.5801439037594547 1</ambient>
                <diffuse>0.5464167892541046 0.6932951350253517 0.22253023363722557 1</diffuse>
                <specular>0.9022550019258972 0.9029306286118689 0.5969458319897258 1</specular>
                <emissive>0 0 0 0</emissive>
            </material>
        </visual>
    </link>

    <joint name="palm_palm_fake" type="fixed">
        <child>palm_fake</child>
        <parent>palm</parent>
        <axis>

            <xyz>0 -1 0</xyz>
         </axis>
    </joint>  

    

        

        
            <link name = "thbase">
                <pose frame=''>-0.034 -0.0028710000000000003 0.176679 0.870557 0.572429 -2.5703</pose>
                <inertial>
                    <pose frame=''>0 0 0 0 0 0</pose>
                    <mass>0.01</mass>
                    <inertia>
                        <ixx>1.6e-07</ixx>
                        <ixy>0</ixy>
                        <ixz>0</ixz>
                        <iyy>1.6e-07</iyy>
                        <iyz>0</iyz>
                        <izz>1.6e-07</izz>
                    </inertia>
                </inertial>
                <visual name='visual_thbase_link'>
                
                    <geometry>
                        <box>
                            <size>0.001 0.001 0.001</size>
                        </box>
                    </geometry>
                    <material>
                        <ambient>0.22548925451302737 0.41316625643942884 0.8955428888023961 1</ambient>
                        <diffuse>0.21500044778656002 0.24881725886484807 0.19502735781638925 1</diffuse>
                        <specular>0.3746275024844079 0.7710816343085363 0.29790152409138215 1</specular>
                        <emissive>0 0 0 0</emissive>
                    </material>
                </visual>
                <collision name='collision_thbase_link'>
                    <pose frame=''>0 0 0 0 0 0</pose>
                    <geometry>
                
                        <sphere>
                            <radius>0.011</radius>
                        </sphere>
                
                    </geometry>
                </collision>
            </link>
            <link name = "thproximal">
                
                <pose frame=''>-0.034 -0.0028710000000000003 0.176679 0.870557 0.572429 -2.5703</pose>
                <inertial>
                    <pose frame=''>0 0 0.021111 0 0 0</pose>
                    <mass>0.04</mass>
                    <inertia>
                        <ixx>1.36e-05</ixx>
                        <ixy>0</ixy>
                        <ixz>0</ixz>
                        <iyy>1.36e-05</iyy>
                        <iyz>0</iyz>
                        <izz>3.13e-06</izz>
                    </inertia>
                </inertial>
                
                <visual name='visual_thproximal_link'>
                
                    <geometry>
                        <mesh>
                            <scale>0.001 0.001 0.001</scale>
                            <uri>/meshes/TH3_z.dae</uri>
                        </mesh>
                    </geometry>
                    <material>
                        <ambient>0.14779279348874863 0.4225523107736494 0.3160010848943985 1</ambient>
                        <diffuse>0.9697685043933721 0.372856705049482 0.3478778469236976 1</diffuse>
                        <specular>0.5989944237737346 0.5323005490910239 0.05493905777571162 1</specular>
                        <emissive>0 0 0 0</emissive>
                    </material>
                </visual>
                <collision name='collision_thproximal_link'>
                    <geometry>
                        <mesh>
                            <scale>0.001 0.001 0.001</scale>
                            <uri>/meshes/TH3_z_c.dae</uri>
                        </mesh>
                    </geometry>
                </collision>
            </link>
            <link name = "thhub">
                <pose frame=''>-0.06087000000000001 0.014400999999999999 0.197263 0.870557 0.572429 -2.5703</pose>
                <inertial>
                    <pose frame=''>0 0 0 0 0 0</pose>
                    <mass>0.005</mass>
                    <inertia>
                        <ixx>1.0e-06</ixx>
                        <ixy>0</ixy>
                        <ixz>0</ixz>
                        <iyy>1.0e-06</iyy>
                        <iyz>0</iyz>
                        <izz>3.0e-07</izz>
                    </inertia>
                </inertial>
                <visual name='visual_thhub_link'>
                
                    <geometry>
                        <box>
                            <size>0.001 0.001 0.001</size>
                        </box>
                    </geometry>
                    <material>
                
                    </material>
                </visual>
                <collision name='collision_thhub_link'>
                    <geometry>
                        <box>
                            <size>0.001 0.001 0.001</size>
                        </box>
                    </geometry>
                </collision>
            </link>
            <link name = "thmiddle">
                
                <pose frame=''>-0.06087000000000001 0.014400999999999999 0.197263 0.870557 0.572429 -2.5703</pose>
                <inertial>
                    <pose frame=''>0 0 0.16 0 0 0</pose>
                    <mass>0.02</mass>
                    <inertia>
                        <ixx>5.1e-06</ixx>
                        <ixy>0</ixy>
                        <ixz>0</ixz>
                        <iyy>5.1e-06</iyy>
                        <iyz>0</iyz>
                        <izz>1.21e-06</izz>
                    </inertia>
                </inertial>
                
                <visual name='visual_thmiddle_link'>
                
                    <geometry>
                        <mesh>
                            <scale>0.001 0.001 0.001</scale>
                            <uri>/meshes/TH2_z.dae</uri>
                        </mesh>
                    </geometry>
                    <material>
                        <ambient>0.10953102569441509 0.1683229794004928 0.2352738737290555 1</ambient>
                        <diffuse>0.10127969043343754 0.4739749033241317 0.8463603928160619 1</diffuse>
                        <specular>0.8622076236846772 0.7528444683804513 0.28657609936347395 1</specular>
                        <emissive>0 0 0 0</emissive>
                    </material>
                </visual>
                
                <collision name='collision_thmiddle_link'>
                    <geometry>
                        <mesh>
                            <scale>0.001 0.001 0.001</scale>
                            <uri>/meshes/TH2_z_c.dae</uri>
                        </mesh>
                    </geometry>
                </collision>
            </link>
            <link name = "thdistal">
                
                <pose frame=''>-0.083498 0.028946 0.214596 -0.785398 0.698132 1.5707999999999998</pose>
                <inertial>
                    <pose frame=''>0 0 0.014559 0 0 0</pose>
                    <mass>0.016</mass>
                    <inertia>
                        <ixx>2.1e-06</ixx>
                        <ixy>0</ixy>
                        <ixz>0</ixz>
                        <iyy>2.2e-06</iyy>
                        <iyz>0</iyz>
                        <izz>1.0e-06</izz>
                    </inertia>
                </inertial>
                
                <visual name='visual_thdistal_link'>
                
                    <geometry>
                        <mesh>
                            <scale>0.001 0.001 0.001</scale>
                            <uri>/meshes/TH1_z.dae</uri>
                        </mesh>
                    </geometry>
                    <material>
                        <ambient>0.6667922101032459 0.2733993374733422 0.7603557711031929 1</ambient>
                        <diffuse>0.5473632877216151 0.3107981242294021 0.7709482272041515 1</diffuse>
                        <specular>0.5707997850287401 0.2825468657247151 0.1985437771170332 1</specular>
                        <emissive>0 0 0 0</emissive>
                    </material>
                </visual>
                <collision name='collision_thdistal_link'>
                    <geometry>
                        <mesh>
                            <scale>0.001 0.001 0.001</scale>
                            <uri>/meshes/TH1_z.dae</uri>
                        </mesh>
                    </geometry>
                </collision>
            </link>
                
            <link name = "fingertip_TH">
                    <!-- This link is for visulaization only-->
                    <pose frame=''>-0.09338880000000001 0.0389455 0.23366230000000002 -0.785398 0 0</pose>
                    <inertial>
                        <pose frame=''>0 0 0.0 0 0 0</pose>
                        <mass>1.0e-94</mass>
                        <inertia>
                            <ixx>0.0</ixx>
                            <ixy>0</ixy>
                            <ixz>0</ixz>
                            <iyy>0.0</iyy>
                            <iyz>0</iyz>
                            <izz>0.0</izz>
                        </inertia>
                    </inertial>
                    <visual name='visual_fingertip'>
                        <geometry>
                            <sphere>
                            <radius>0.005</radius>
                            </sphere>
                        </geometry>
                        <material>
                            <ambient>0.5672216218105076 0.531815859282997 0.5801439037594547 1</ambient>
                            <diffuse>0.5464167892541046 0.6932951350253517 0.22253023363722557 1</diffuse>
                            <specular>0.9022550019258972 0.9029306286118689 0.5969458319897258 1</specular>
                            <emissive>0 0 0 0</emissive>
                        </material>
                    </visual>
            </link>
                
                
            
                <joint name ="THJ5"  type ="revolute">
                    <child>thbase</child>
                    <parent>palm</parent>
                    <axis>
                        <xyz>0 0 0.541675</xyz>
                        <limit>
                            <lower>-1.0472 </lower>
                            <upper>1.0472 </upper>
                            <effort>5.0 </effort>
                            <velocity>4.0 </velocity>
                        </limit>
                        <dynamics>
                            <damping>0.2</damping>
                            <friction>0</friction>
                        </dynamics>
                    </axis>
                </joint>
            
                <joint name ="THJ4"  type ="revolute">
                    <child>thproximal</child>
                    <parent>thbase</parent>
                    <axis>
                        <xyz>-0.707107 -0.454519 -0.541675</xyz>
                        <limit>
                            <lower>0 </lower>
                            <upper>1.22173 </upper>
                            <effort>3.0 </effort>
                            <velocity>4.0 </velocity>
                        </limit>
                        <dynamics>
                            <damping>0.2</damping>
                            <friction>0</friction>
                        </dynamics>
                    </axis>
                </joint>
            
                <joint name ="THJ2"  type ="revolute">
                    <child>thmiddle</child>
                    <parent>thhub</parent>
                    <axis>
                        <xyz>0 -0.766044 0.642788</xyz>
                        <limit>
                            <lower>-0.698132 </lower>
                            <upper>0.698132 </upper>
                            <effort>2.0 </effort>
                            <velocity>2.0 </velocity>
                        </limit>
                        <dynamics>
                            <damping>0.1</damping>
                            <friction>0</friction>
                        </dynamics>
                    </axis>
                </joint>
            
                <joint name ="THJ1"  type ="revolute">
                    <child>thdistal</child>
                    <parent>thmiddle</parent>
                    <axis>
                        <xyz>1 0 0</xyz>
                        <limit>
                            <lower>0 </lower>
                            <upper>1.5708 </upper>
                            <effort>1.0 </effort>
                            <velocity>4.0 </velocity>
                        </limit>
                        <dynamics>
                            <damping>0.2</damping>
                            <friction>0</friction>
                        </dynamics>
                    </axis>
                </joint>
            
            <joint name ="THJ3"  type ="fixed">
                <child>thhub</child>
                <parent>thproximal</parent>
                <axis>
                    <xyz>1 0 0</xyz>
                </axis>
            </joint>
            
            <joint name="THJ0" type="fixed">
                <child>fingertip_TH</child>
                <parent>thdistal</parent>
                <axis>
            
                    <xyz>0 -1 0</xyz>
                </axis>
            </joint>
                
    
 
    

    
    
            <link name =  "ws_TH">
                <pose frame=''>0 0 0 0.0 0.0 0.0</pose>
                <inertial>
                    <pose frame=''>0 0 0.09 0 0 0</pose>
                    <mass>1.8</mass>
                    <inertia>
                        <ixx>0.108</ixx>
                        <ixy>0</ixy>
                        <ixz>0</ixz>
                        <iyy>0.108</iyy>
                        <iyz>0</iyz>
                        <izz>0.054</izz>
                    </inertia>
                </inertial>

                <visual name='visual_ws_TH'>

                    <geometry>
                        <mesh>
                             <scale>1 1 1</scale>
                            <uri>/meshes/ws/TH/TH_ws.dae</uri>
                        </mesh>
                    </geometry>
                    <material>
                        <ambient>0.0 0.0 0.0 0.2</ambient>
                        <diffuse>0.0 0.0 0.0 0.2</diffuse>
                        <specular>0.0 0.0 0.0 0.2</specular>
                        <emissive>0 0 0 0</emissive>
                    </material>
                </visual>
            </link>

            <joint name = "ws_TH"  type ="fixed">
               <child>ws_TH</child>
                <parent>forearm</parent>
                <axis>
                    <xyz></xyz>
                </axis>
            </joint>
    
   
   
 
  </model>

</sdf>